Workbook

Sheet Параметры
A1: ПАРАМЕТРЫ РАСЧЁТА
A3: Маржа (% от себестоимости): | D3: 0.35
A4: Рабочих дней в месяце: | D4: 22
A6: № | B6: Роль | C6: Грейд | D6: Ставка в сутки, ₽
A7: 1 | B7: Руководитель проекта (PM) | C7: Senior | D7: 40000
A8: 2 | B8: Бизнес-аналитик (BA) | C8: Middle+ | D8: 25000
A9: 3 | B9: Системный архитектор | C9: Senior | D9: 45000
A10: 4 | B10: Backend-разработчик (Java) | C10: Middle+ | D10: 35000
A11: 5 | B11: Frontend-разработчик (React) | C11: Middle | D11: 30000
A12: 6 | B12: DevOps / инфраструктура | C12: Middle+ | D12: 40000
A13: 7 | B13: DBA (PostgreSQL) | C13: Middle | D13: 35000
A14: 8 | B14: QA-инженер | C14: Middle | D14: 25000
A15: 9 | B15: Специалист ИБ | C15: Middle+ | D15: 25000
A16: 10 | B16: Нагрузочное тестирование | C16: Middle | D16: 25000
A17: 11 | B17: Инженер поддержки (L1/L2) | C17: Junior+ | D17: 15000
A18: 12 | B18: Сервис-менеджер | C18: Middle | D18: 15000
A20: Жёлтые — редактируемые | Зелёные — формулы | Оранжевые — маржа

Sheet Внедрение
A1: РАСЧЁТ СТОИМОСТИ ВНЕДРЕНИЯ
A3: Этап / Задача | B3: Роль | C3: Кол-во чел. | D3: Длит-ть этапа (дн) | E3: Загрузка (%) | F3: Чел-дни | G3: Ставка ₽/день | H3: Стоимость ₽
A4: 1. Предпроект и проектирование (1.5 мес)
A5: Управление проектом | B5: =Параметры!B7 -> Руководитель проекта (PM) | C5: 1 | D5: 33 | E5: 1 | F5: =C5*D5*E5 -> 33 | G5: =Параметры!D7 -> 40000 | H5: =F5*G5 -> 1320000
A6: Обследование, сбор требований | B6: =Параметры!B8 -> Бизнес-аналитик (BA) | C6: 1 | D6: 33 | E6: 1 | F6: =C6*D6*E6 -> 33 | G6: =Параметры!D8 -> 25000 | H6: =F6*G6 -> 825000
A7: Проектирование архитектуры | B7: =Параметры!B9 -> Системный архитектор | C7: 1 | D7: 33 | E7: 0.5 | F7: =C7*D7*E7 -> 16.5 | G7: =Параметры!D9 -> 45000 | H7: =F7*G7 -> 742500
A8: Модель угроз, требования ИБ | B8: =Параметры!B15 -> Специалист ИБ | C8: 1 | D8: 33 | E8: 0.3 | F8: =C8*D8*E8 -> 9.9 | G8: =Параметры!D15 -> 25000 | H8: =F8*G8 -> 247500
A9: Итого этап | F9: =SUM(F5:F8) -> 92.4 | H9: =SUM(H5:H8) -> 3135000
A11: 2. Инсталляция и настройка (1.5 мес)
A12: Управление проектом | B12: =Параметры!B7 -> Руководитель проекта (PM) | C12: 1 | D12: 28 | E12: 0.5 | F12: =C12*D12*E12 -> 14 | G12: =Параметры!D7 -> 40000 | H12: =F12*G12 -> 560000
A13: Развёртывание k8s, инфраструктуры | B13: =Параметры!B12 -> DevOps / инфраструктура | C13: 1 | D13: 28 | E13: 1 | F13: =C13*D13*E13 -> 28 | G13: =Параметры!D12 -> 40000 | H13: =F13*G13 -> 1120000
A14: Настройка PostgreSQL HA | B14: =Параметры!B13 -> DBA (PostgreSQL) | C14: 1 | D14: 28 | E14: 0.5 | F14: =C14*D14*E14 -> 14 | G14: =Параметры!D13 -> 35000 | H14: =F14*G14 -> 490000
A15: Настройка сервисов, конфигурация | B15: =Параметры!B10 -> Backend-разработчик (Java) | C15: 1 | D15: 28 | E15: 0.5 | F15: =C15*D15*E15 -> 14 | G15: =Параметры!D10 -> 35000 | H15: =F15*G15 -> 490000
A16: Согласование ИБ, сетевые правила | B16: =Параметры!B15 -> Специалист ИБ | C16: 1 | D16: 28 | E16: 0.2 | F16: =C16*D16*E16 -> 5.6 | G16: =Параметры!D15 -> 25000 | H16: =F16*G16 -> 140000
A17: Итого этап | F17: =SUM(F12:F16) -> 75.6 | H17: =SUM(H12:H16) -> 2800000
A19: 3. Интеграция и кастомизация (2.5 мес)
A20: Управление проектом | B20: =Параметры!B7 -> Руководитель проекта (PM) | C20: 1 | D20: 55 | E20: 0.5 | F20: =C20*D20*E20 -> 27.5 | G20: =Параметры!D7 -> 40000 | H20: =F20*G20 -> 1100000
A21: Уточнение требований, приёмка | B21: =Параметры!B8 -> Бизнес-аналитик (BA) | C21: 1 | D21: 55 | E21: 0.5 | F21: =C21*D21*E21 -> 27.5 | G21: =Параметры!D8 -> 25000 | H21: =F21*G21 -> 687500
A22: Интеграция AD/LDAP, webhooks | B22: =Параметры!B10 -> Backend-разработчик (Java) | C22: 1 | D22: 55 | E22: 1 | F22: =C22*D22*E22 -> 55 | G22: =Параметры!D10 -> 35000 | H22: =F22*G22 -> 1925000
A23: Доработка API, справочники | B23: =Параметры!B10 -> Backend-разработчик (Java) | C23: 1 | D23: 55 | E23: 1 | F23: =C23*D23*E23 -> 55 | G23: =Параметры!D10 -> 35000 | H23: =F23*G23 -> 1925000
A24: Кастомизация дашбордов, отчётов | B24: =Параметры!B11 -> Frontend-разработчик (React) | C24: 1 | D24: 55 | E24: 1 | F24: =C24*D24*E24 -> 55 | G24: =Параметры!D11 -> 30000 | H24: =F24*G24 -> 1650000
A25: CI/CD, деплой доработок | B25: =Параметры!B12 -> DevOps / инфраструктура | C25: 1 | D25: 55 | E25: 0.3 | F25: =C25*D25*E25 -> 16.5 | G25: =Параметры!D12 -> 40000 | H25: =F25*G25 -> 660000
A26: Итого этап | F26: =SUM(F20:F25) -> 236.5 | H26: =SUM(H20:H25) -> 7947500
A28: 4. Тестирование (1.5 мес)
A29: Управление проектом | B29: =Параметры!B7 -> Руководитель проекта (PM) | C29: 1 | D29: 28 | E29: 0.3 | F29: =C29*D29*E29 -> 8.4 | G29: =Параметры!D7 -> 40000 | H29: =F29*G29 -> 336000
A30: Функциональное, интеграционное | B30: =Параметры!B14 -> QA-инженер | C30: 1 | D30: 28 | E30: 1 | F30: =C30*D30*E30 -> 28 | G30: =Параметры!D14 -> 25000 | H30: =F30*G30 -> 700000
A31: Нагрузочное (10K агентов) | B31: =Параметры!B16 -> Нагрузочное тестирование | C31: 1 | D31: 28 | E31: 0.5 | F31: =C31*D31*E31 -> 14 | G31: =Параметры!D16 -> 25000 | H31: =F31*G31 -> 350000
A32: Исправление дефектов | B32: =Параметры!B10 -> Backend-разработчик (Java) | C32: 1 | D32: 28 | E32: 0.5 | F32: =C32*D32*E32 -> 14 | G32: =Параметры!D10 -> 35000 | H32: =F32*G32 -> 490000
A33: Тестирование ИБ, пентест | B33: =Параметры!B15 -> Специалист ИБ | C33: 1 | D33: 28 | E33: 0.5 | F33: =C33*D33*E33 -> 14 | G33: =Параметры!D15 -> 25000 | H33: =F33*G33 -> 350000
A34: Итого этап | F34: =SUM(F29:F33) -> 78.4 | H34: =SUM(H29:H33) -> 2226000
A36: 5. Пилот и раскатка (2.5 мес)
A37: Управление, координация, обучение | B37: =Параметры!B7 -> Руководитель проекта (PM) | C37: 1 | D37: 55 | E37: 1 | F37: =C37*D37*E37 -> 55 | G37: =Параметры!D7 -> 40000 | H37: =F37*G37 -> 2200000
A38: Раскатка агентов (GPO/SCCM) | B38: =Параметры!B12 -> DevOps / инфраструктура | C38: 1 | D38: 55 | E38: 0.5 | F38: =C38*D38*E38 -> 27.5 | G38: =Параметры!D12 -> 40000 | H38: =F38*G38 -> 1100000
A39: Поддержка пилота | B39: =Параметры!B17 -> Инженер поддержки (L1/L2) | C39: 1 | D39: 55 | E39: 1 | F39: =C39*D39*E39 -> 55 | G39: =Параметры!D17 -> 15000 | H39: =F39*G39 -> 825000
A40: Обучение пользователей | B40: =Параметры!B8 -> Бизнес-аналитик (BA) | C40: 1 | D40: 55 | E40: 0.5 | F40: =C40*D40*E40 -> 27.5 | G40: =Параметры!D8 -> 25000 | H40: =F40*G40 -> 687500
A41: Исправление замечаний | B41: =Параметры!B10 -> Backend-разработчик (Java) | C41: 1 | D41: 55 | E41: 0.3 | F41: =C41*D41*E41 -> 16.5 | G41: =Параметры!D10 -> 35000 | H41: =F41*G41 -> 577500
A42: Итого этап | F42: =SUM(F37:F41) -> 181.5 | H42: =SUM(H37:H41) -> 5390000
A45: СЕБЕСТОИМОСТЬ ВНЕДРЕНИЯ: | H45: =H9+H17+H26+H34+H42 -> 21498500
A46: МАРЖА: | H46: =H45*Параметры!D3 -> 7524475
A47: ИТОГО ДЛЯ ЗАКАЗЧИКА: | H47: =H45+H46 -> 29022975
...

Sheet Сопровождение
A1: РАСЧЁТ ГОДОВОГО СОПРОВОЖДЕНИЯ
A3: Направление | B3: Роль | C3: Кол-во чел. | D3: Месяцев | E3: Загрузка (%) | F3: Чел-дни/год | G3: Ставка ₽/день | H3: Стоимость ₽/год
A4: L1: приём обращений, переустановка агентов | B4: =Параметры!B17 -> Инженер поддержки (L1/L2) | C4: 1 | D4: 12 | E4: 0.3 | F4: =C4*D4*Параметры!$D$4*E4 -> 79.2 | G4: =Параметры!D17 -> 15000 | H4: =F4*G4 -> 1188000
A5: L2: администрирование, политики, мониторинг | B5: =Параметры!B17 -> Инженер поддержки (L1/L2) | C5: 1 | D5: 12 | E5: 0.5 | F5: =C5*D5*Параметры!$D$4*E5 -> 132 | G5: =Параметры!D17 -> 15000 | H5: =F5*G5 -> 1980000
A6: L3: багфиксы, доработки, обновления | B6: =Параметры!B10 -> Backend-разработчик (Java) | C6: 1 | D6: 12 | E6: 0.2 | F6: =C6*D6*Параметры!$D$4*E6 -> 52.8 | G6: =Параметры!D10 -> 35000 | H6: =F6*G6 -> 1848000
A7: DevOps: обновление, мониторинг, бэкапы | B7: =Параметры!B12 -> DevOps / инфраструктура | C7: 1 | D7: 12 | E7: 0.1 | F7: =C7*D7*Параметры!$D$4*E7 -> 26.4 | G7: =Параметры!D12 -> 40000 | H7: =F7*G7 -> 1056000
A8: Сервис-менеджмент, отчётность | B8: =Параметры!B18 -> Сервис-менеджер | C8: 1 | D8: 12 | E8: 0.2 | F8: =C8*D8*Параметры!$D$4*E8 -> 52.8 | G8: =Параметры!D18 -> 15000 | H8: =F8*G8 -> 792000
A10: СЕБЕСТОИМОСТЬ (ГОД): | H10: =SUM(H4:H8) -> 6864000
A11: МАРЖА: | H11: =H10*Параметры!D3 -> 2402400
A12: ИТОГО ДЛЯ ЗАКАЗЧИКА (ГОД): | H12: =H10+H11 -> 9266400
A14: Человеко-дней в год: | F14: =SUM(F4:F8) -> 343.2

Sheet Сводка
A1: СВОДНАЯ ТАБЛИЦА
A3: Статья | B3: Себестоимость, ₽ | C3: Для заказчика, ₽
A4: Внедрение (разовое) | B4: =Внедрение!H45 -> 21498500 | C4: =Внедрение!H47 -> 29022975
A5: Сопровождение (год) | B5: =Сопровождение!H10 -> 6864000 | C5: =Сопровождение!H12 -> 9266400
A6: Лицензия (год) — заполнить вручную | B6: 0 | C6: 0
A8: ИТОГО 1-й ГОД: | B8: =B4+B5+B6 -> 28362500 | C8: =C4+C5+C6 -> 38289375
A9: 2-й год и далее (сопр. + лицензия): | B9: =B5+B6 -> 6864000 | C9: =C5+C6 -> 9266400
A11: Маржа: | B11: =Параметры!D3 -> 0.35
A13: TCO 3 ГОДА: | C13: =C8+C9*2 -> 56822175
A14: TCO 5 ЛЕТ: | C14: =C8+C9*4 -> 75354975
